#name : try { ...} catch ( ... ) { ... }
# --
try {
    $0
} catch (const ${1:std::exception}& ${2:e}) {
    std::cout << $2.what() << std::endl;
}